<?xml version="1.0"?>
<!-- =================================================================================== -->
<!-- |    This document was autogenerated by xacro from ur5e.xacro                     | -->
<!-- |    EDITING THIS FILE BY HAND IS NOT RECOMMENDED                                 | -->
<!-- =================================================================================== -->
<robot name="ur5e">
	<!--
	Base UR robot series xacro macro.
	
	NOTE: this is NOT a URDF. It cannot directly be loaded by consumers
	expecting a flattened '.urdf' file. See the top-level '.xacro' for that
	(but note: that .xacro must still be processed by the xacro command).
	
	For use in '.launch' files: use one of the 'load_urX.launch' convenience
	launch files.
	
	This file models the base kinematic chain of a UR robot, which then gets
	parameterised by various configuration files to convert it into a UR3(e),
	UR5(e), UR10(e) or UR16e.
	
	NOTE: the default kinematic parameters (ie: link lengths, frame locations,
	offets, etc) do not correspond to any particular robot. They are defaults
	only. There WILL be non-zero offsets between the Forward Kinematics results
	in TF (ie: robot_state_publisher) and the values reported by the Teach
	Pendant.
	
	For accurate (and robot-specific) transforms, the 'kinematics_parameters_file'
	parameter MUST point to a .yaml file containing the appropriate values for
	the targetted robot.
	
	If using the UniversalRobots/Universal_Robots_ROS_Driver, follow the steps
	described in the readme of that repository to extract the kinematic
	calibration from the controller and generate the required .yaml file.
	
	Main author of the migration to yaml configs: Ludovic Delval.
	
	Contributors to previous versions (in no particular order):
	
	- Felix Messmer
	- Kelsey Hawkins
	- Wim Meeussen
	- Shaun Edwards
	- Nadia Hammoudeh Garcia
	- Dave Hershberger
	- G. vd. Hoorn
	- Philip Long
	- Dave Coleman
	- Miguel Prada
	- Mathias Luedtke
	- Marcel Schnirring
	- Felix von Drigalski
	- Felix Exner
	- Jimmy Da Silva
	- Ajit Krisshna N L
	- Muhammad Asif Rana
	-->
	<!--
	NOTE: the macro defined in this file is NOT part of the public API of this
	package. Users CANNOT rely on this file being available, or stored in
	this location. Nor can they rely on the existence of the macro.
	-->
	<transmission name="shoulder_pan_trans">
		<type>
			transmission_interface/SimpleTransmission
		</type>
		<joint name="shoulder_pan_joint">
			<hardwareInterface>
				hardware_interface/PositionJointInterface
			</hardwareInterface>
		</joint>
		<actuator name="shoulder_pan_motor">
			<mechanicalReduction>
				1
			</mechanicalReduction>
		</actuator>
	</transmission>
	<transmission name="shoulder_lift_trans">
		<type>
			transmission_interface/SimpleTransmission
		</type>
		<joint name="shoulder_lift_joint">
			<hardwareInterface>
				hardware_interface/PositionJointInterface
			</hardwareInterface>
		</joint>
		<actuator name="shoulder_lift_motor">
			<mechanicalReduction>
				1
			</mechanicalReduction>
		</actuator>
	</transmission>
	<transmission name="elbow_trans">
		<type>
			transmission_interface/SimpleTransmission
		</type>
		<joint name="elbow_joint">
			<hardwareInterface>
				hardware_interface/PositionJointInterface
			</hardwareInterface>
		</joint>
		<actuator name="elbow_motor">
			<mechanicalReduction>
				1
			</mechanicalReduction>
		</actuator>
	</transmission>
	<transmission name="wrist_1_trans">
		<type>
			transmission_interface/SimpleTransmission
		</type>
		<joint name="wrist_1_joint">
			<hardwareInterface>
				hardware_interface/PositionJointInterface
			</hardwareInterface>
		</joint>
		<actuator name="wrist_1_motor">
			<mechanicalReduction>
				1
			</mechanicalReduction>
		</actuator>
	</transmission>
	<transmission name="wrist_2_trans">
		<type>
			transmission_interface/SimpleTransmission
		</type>
		<joint name="wrist_2_joint">
			<hardwareInterface>
				hardware_interface/PositionJointInterface
			</hardwareInterface>
		</joint>
		<actuator name="wrist_2_motor">
			<mechanicalReduction>
				1
			</mechanicalReduction>
		</actuator>
	</transmission>
	<transmission name="wrist_3_trans">
		<type>
			transmission_interface/SimpleTransmission
		</type>
		<joint name="wrist_3_joint">
			<hardwareInterface>
				hardware_interface/PositionJointInterface
			</hardwareInterface>
		</joint>
		<actuator name="wrist_3_motor">
			<mechanicalReduction>
				1
			</mechanicalReduction>
		</actuator>
	</transmission>
	<!-- links: main serial chain -->
	<link name="base_link" />
	<link name="base_link_inertia">
		<visual>
			<origin rpy="0 0 3.141592653589793" xyz="0 0 0" />
			<geometry>
				<mesh filename="package://ur_description/meshes/ur5e/visual/base.dae" />
			</geometry>
			<material name="LightGrey">
				<color rgba="0.7 0.7 0.7 1.0" />
			</material>
		</visual>
		<collision>
			<origin rpy="0 0 3.141592653589793" xyz="0 0 0" />
			<geometry>
				<mesh filename="package://ur_description/meshes/ur5e/collision/base.stl" />
			</geometry>
		</collision>
		<inertial>
			<mass value="4.0" />
			<origin rpy="0 0 0" xyz="0 0 0" />
			<inertia ixx="0.00443333156" ixy="0.0" ixz="0.0" iyy="0.00443333156" iyz="0.0" izz="0.0072" />
		</inertial>
	</link>
	<link name="shoulder_link">
		<visual>
			<origin rpy="0 0 3.141592653589793" xyz="0 0 0" />
			<geometry>
				<mesh filename="package://ur_description/meshes/ur5e/visual/shoulder.dae" />
			</geometry>
			<material name="LightGrey">
				<color rgba="0.7 0.7 0.7 1.0" />
			</material>
		</visual>
		<collision>
			<origin rpy="0 0 3.141592653589793" xyz="0 0 0" />
			<geometry>
				<mesh filename="package://ur_description/meshes/ur5e/collision/shoulder.stl" />
			</geometry>
		</collision>
		<inertial>
			<mass value="3.7" />
			<origin rpy="0 0 0" xyz="0 0 0" />
			<inertia ixx="0.010267495893" ixy="0.0" ixz="0.0" iyy="0.010267495893" iyz="0.0" izz="0.00666" />
		</inertial>
	</link>
	<link name="upper_arm_link">
		<visual>
			<origin rpy="1.5707963267948966 0 -1.5707963267948966" xyz="0 0 0.138" />
			<geometry>
				<mesh filename="package://ur_description/meshes/ur5e/visual/upperarm.dae" />
			</geometry>
			<material name="LightGrey">
				<color rgba="0.7 0.7 0.7 1.0" />
			</material>
		</visual>
		<collision>
			<origin rpy="1.5707963267948966 0 -1.5707963267948966" xyz="0 0 0.138" />
			<geometry>
				<mesh filename="package://ur_description/meshes/ur5e/collision/upperarm.stl" />
			</geometry>
		</collision>
		<inertial>
			<mass value="8.393" />
			<origin rpy="0 1.5707963267948966 0" xyz="-0.2125 0.0 0.138" />
			<inertia ixx="0.1338857818623325" ixy="0.0" ixz="0.0" iyy="0.1338857818623325" iyz="0.0" izz="0.0151074" />
		</inertial>
	</link>
	<link name="forearm_link">
		<visual>
			<origin rpy="1.5707963267948966 0 -1.5707963267948966" xyz="0 0 0.007" />
			<geometry>
				<mesh filename="package://ur_description/meshes/ur5e/visual/forearm.dae" />
			</geometry>
			<material name="LightGrey">
				<color rgba="0.7 0.7 0.7 1.0" />
			</material>
		</visual>
		<collision>
			<origin rpy="1.5707963267948966 0 -1.5707963267948966" xyz="0 0 0.007" />
			<geometry>
				<mesh filename="package://ur_description/meshes/ur5e/collision/forearm.stl" />
			</geometry>
		</collision>
		<inertial>
			<mass value="2.275" />
			<origin rpy="0 1.5707963267948966 0" xyz="-0.1961 0.0 0.007" />
			<inertia ixx="0.031209355099586295" ixy="0.0" ixz="0.0" iyy="0.031209355099586295" iyz="0.0" izz="0.004095" />
		</inertial>
	</link>
	<link name="wrist_1_link">
		<visual>
			<!-- TODO: Move this to a parameter -->
			<origin rpy="1.5707963267948966 0 0" xyz="0 0 -0.127" />
			<geometry>
				<mesh filename="package://ur_description/meshes/ur5e/visual/wrist1.dae" />
			</geometry>
			<material name="LightGrey">
				<color rgba="0.7 0.7 0.7 1.0" />
			</material>
		</visual>
		<collision>
			<origin rpy="1.5707963267948966 0 0" xyz="0 0 -0.127" />
			<geometry>
				<mesh filename="package://ur_description/meshes/ur5e/collision/wrist1.stl" />
			</geometry>
		</collision>
		<inertial>
			<mass value="1.219" />
			<origin rpy="0 0 0" xyz="0 0 0" />
			<inertia ixx="0.0025598989760400002" ixy="0.0" ixz="0.0" iyy="0.0025598989760400002" iyz="0.0" izz="0.0021942" />
		</inertial>
	</link>
	<link name="wrist_2_link">
		<visual>
			<origin rpy="0 0 0" xyz="0 0 -0.0997" />
			<geometry>
				<mesh filename="package://ur_description/meshes/ur5e/visual/wrist2.dae" />
			</geometry>
			<material name="LightGrey">
				<color rgba="0.7 0.7 0.7 1.0" />
			</material>
		</visual>
		<collision>
			<origin rpy="0 0 0" xyz="0 0 -0.0997" />
			<geometry>
				<mesh filename="package://ur_description/meshes/ur5e/collision/wrist2.stl" />
			</geometry>
		</collision>
		<inertial>
			<mass value="1.219" />
			<origin rpy="0 0 0" xyz="0 0 0" />
			<inertia ixx="0.0025598989760400002" ixy="0.0" ixz="0.0" iyy="0.0025598989760400002" iyz="0.0" izz="0.0021942" />
		</inertial>
	</link>
	<link name="wrist_3_link">
		<visual>
			<origin rpy="1.5707963267948966 0 0" xyz="0 0 -0.0989" />
			<geometry>
				<mesh filename="package://ur_description/meshes/ur5e/visual/wrist3.dae" />
			</geometry>
			<material name="LightGrey">
				<color rgba="0.7 0.7 0.7 1.0" />
			</material>
		</visual>
		<collision>
			<origin rpy="1.5707963267948966 0 0" xyz="0 0 -0.0989" />
			<geometry>
				<mesh filename="package://ur_description/meshes/ur5e/collision/wrist3.stl" />
			</geometry>
		</collision>
		<inertial>
			<mass value="0.1879" />
			<origin rpy="0 0 0" xyz="0.0 0.0 -0.0229" />
			<inertia ixx="9.890410052167731e-05" ixy="0.0" ixz="0.0" iyy="9.890410052167731e-05" iyz="0.0" izz="0.0001321171875" />
		</inertial>
	</link>
	<!-- joints: main serial chain -->
	<joint name="base_link-base_link_inertia" type="fixed">
		<parent link="base_link" />
		<child link="base_link_inertia" />
		<!--
		'base_link' is REP-103 aligned (so X+ forward), while the internal
		frames of the robot/controller have X+ pointing backwards.
		Use the joint between 'base_link' and 'base_link_inertia' (a dummy
		link/frame) to introduce the necessary rotation over Z (of pi rad).
		-->
		<origin rpy="0 0 3.141592653589793" xyz="0 0 0" />
	</joint>
	<joint name="shoulder_pan_joint" type="revolute">
		<parent link="base_link_inertia" />
		<child link="shoulder_link" />
		<origin rpy="0 0 0" xyz="0 0 0.1625" />
		<axis xyz="0 0 1" />
		<limit effort="150.0" lower="-6.283185307179586" upper="6.283185307179586" velocity="3.141592653589793" />
		<dynamics damping="0" friction="0" />
	</joint>
	<joint name="shoulder_lift_joint" type="revolute">
		<parent link="shoulder_link" />
		<child link="upper_arm_link" />
		<origin rpy="1.570796327 0 0" xyz="0 0 0" />
		<axis xyz="0 0 1" />
		<limit effort="150.0" lower="-6.283185307179586" upper="6.283185307179586" velocity="3.141592653589793" />
		<dynamics damping="0" friction="0" />
	</joint>
	<joint name="elbow_joint" type="revolute">
		<parent link="upper_arm_link" />
		<child link="forearm_link" />
		<origin rpy="0 0 0" xyz="-0.425 0 0" />
		<axis xyz="0 0 1" />
		<limit effort="150.0" lower="-3.141592653589793" upper="3.141592653589793" velocity="3.141592653589793" />
		<dynamics damping="0" friction="0" />
	</joint>
	<joint name="wrist_1_joint" type="revolute">
		<parent link="forearm_link" />
		<child link="wrist_1_link" />
		<origin rpy="0 0 0" xyz="-0.3922 0 0.1333" />
		<axis xyz="0 0 1" />
		<limit effort="28.0" lower="-6.283185307179586" upper="6.283185307179586" velocity="3.141592653589793" />
		<dynamics damping="0" friction="0" />
	</joint>
	<joint name="wrist_2_joint" type="revolute">
		<parent link="wrist_1_link" />
		<child link="wrist_2_link" />
		<origin rpy="1.570796327 0 0" xyz="0 -0.0997 -2.044881182297852e-11" />
		<axis xyz="0 0 1" />
		<limit effort="28.0" lower="-6.283185307179586" upper="6.283185307179586" velocity="3.141592653589793" />
		<dynamics damping="0" friction="0" />
	</joint>
	<joint name="wrist_3_joint" type="revolute">
		<parent link="wrist_2_link" />
		<child link="wrist_3_link" />
		<origin rpy="1.570796326589793 3.141592653589793 3.141592653589793" xyz="0 0.0996 -2.042830148012698e-11" />
		<axis xyz="0 0 1" />
		<limit effort="28.0" lower="-6.283185307179586" upper="6.283185307179586" velocity="3.141592653589793" />
		<dynamics damping="0" friction="0" />
	</joint>
	<!-- ROS-Industrial 'base' frame: base_link to UR 'Base' Coordinates transform -->
	<link name="base" />
	<joint name="base_link-base_fixed_joint" type="fixed">
		<!--
		Note the rotation over Z of pi radians: as base_link is REP-103
		aligned (ie: has X+ forward, Y+ left and Z+ up), this is needed
		to correctly align 'base' with the 'Base' coordinate system of
		the UR controller.
		-->
		<origin rpy="0 0 3.141592653589793" xyz="0 0 0" />
		<parent link="base_link" />
		<child link="base" />
	</joint>
	<!-- ROS-Industrial 'flange' frame: attachment point for EEF models -->
	<link name="flange" />
	<joint name="wrist_3-flange" type="fixed">
		<parent link="wrist_3_link" />
		<child link="flange" />
		<origin rpy="0 -1.5707963267948966 -1.5707963267948966" xyz="0 0 0" />
	</joint>
	<!-- ROS-Industrial 'tool0' frame: all-zeros tool frame -->
	<link name="tool0" />
	<joint name="flange-tool0" type="fixed">
		<!-- default toolframe: X+ left, Y+ up, Z+ front -->
		<origin rpy="1.5707963267948966 0 1.5707963267948966" xyz="0 0 0" />
		<parent link="flange" />
		<child link="tool0" />
	</joint>
	<!-- GRIPPER -->
	<link name="gripper_robotiq_85_base_link">
		<visual>
			<geometry>
				<mesh filename="package://robotiq_description/meshes/visual/2f_85/robotiq_base.dae" />
			</geometry>
		</visual>
		<collision>
			<geometry>
				<mesh filename="package://robotiq_description/meshes/collision/2f_85/robotiq_base.stl" />
			</geometry>
		</collision>
		<inertial>
			<origin xyz="0.0 2.274e-05 0.03232288" rpy="0 0 0" />
			<mass value="6.6320197e-01" />
			<inertia ixx="5.1617816e-04" iyy="5.8802208e-04" izz="3.9462776e-04" ixy="2.936e-8" ixz="0.0" iyz="-3.2296e-7" />
		</inertial>
	</link>
	<link name="gripper_robotiq_85_left_knuckle_link">
		<visual>
			<geometry>
				<mesh filename="package://robotiq_description/meshes/visual/2f_85/left_knuckle.dae" />
			</geometry>
		</visual>
		<collision>
			<geometry>
				<mesh filename="package://robotiq_description/meshes/collision/2f_85/left_knuckle.stl" />
			</geometry>
		</collision>
		<inertial>
			<origin xyz="0.01213197 0.0002 -0.00058647" rpy="0 0 0" />
			<mass value="1.384773208e-02" />
			<inertia ixx="3.5232e-7" iyy="2.31944e-6" izz="2.23136e-6" ixy="0.0" ixz="1.1744e-7" iyz="0" />
		</inertial>
	</link>
	<link name="gripper_robotiq_85_right_knuckle_link">
		<visual>
			<geometry>
				<mesh filename="package://robotiq_description/meshes/visual/2f_85/right_knuckle.dae" />
			</geometry>
		</visual>
		<collision>
			<geometry>
				<mesh filename="package://robotiq_description/meshes/collision/2f_85/right_knuckle.stl" />
			</geometry>
		</collision>
		<inertial>
			<origin xyz="-0.01213197 0.0002 -0.00058647" rpy="0 0 0" />
			<mass value="1.384773208e-02" />
			<inertia ixx="3.5232e-7" iyy="2.31944e-6" izz="2.23136e-6" ixy="0.0" ixz="-1.1744e-7" iyz="0.0" />
		</inertial>
	</link>
	<link name="gripper_robotiq_85_left_finger_link">
		<visual>
			<geometry>
				<mesh filename="package://robotiq_description/meshes/visual/2f_85/left_finger.dae" />
			</geometry>
		</visual>
		<collision>
			<geometry>
				<mesh filename="package://robotiq_description/meshes/collision/2f_85/left_finger.stl" />
			</geometry>
		</collision>
		<inertial>
			<origin xyz="0.00346899 -0.00079447 0.01867121" rpy="0 0 0" />
			<mass value="4.260376752e-02" />
			<inertia ixx="1.385792000000000e-05" iyy="1.183208e-05" izz="5.19672e-06" ixy="0.0" ixz="-2.17264e-06" iyz="0.0" />
		</inertial>
	</link>
	<link name="gripper_robotiq_85_right_finger_link">
		<visual>
			<geometry>
				<mesh filename="package://robotiq_description/meshes/visual/2f_85/right_finger.dae" />
			</geometry>
		</visual>
		<collision>
			<geometry>
				<mesh filename="package://robotiq_description/meshes/collision/2f_85/right_finger.stl" />
			</geometry>
		</collision>
		<inertial>
			<origin xyz="-0.00346899 -5.53e-06 0.01867121" rpy="0 0 0" />
			<mass value="4.260376752000000e-02" />
			<inertia ixx="1.385792e-05" iyy="1.183208e-05" izz="5.19672e-06" ixy="0.0" ixz="2.17264e-06" iyz="0.0" />
		</inertial>
	</link>
	<link name="gripper_robotiq_85_left_inner_knuckle_link">
		<visual>
			<geometry>
				<mesh filename="package://robotiq_description/meshes/visual/2f_85/left_inner_knuckle.dae" />
			</geometry>
		</visual>
		<collision>
			<geometry>
				<mesh filename="package://robotiq_description/meshes/collision/2f_85/left_inner_knuckle.stl" />
			</geometry>
		</collision>
		<inertial>
			<origin xyz="0.01897699 0.00015001 0.02247101" rpy="0 0 0" />
			<mass value="2.969376448e-02" />
			<inertia ixx="9.57136e-06" iyy="8.69056e-06" izz="8.19144e-06" ixy="0.0" ixz="-3.93424e-06" iyz="0.0" />
		</inertial>
	</link>
	<link name="gripper_robotiq_85_right_inner_knuckle_link">
		<visual>
			<geometry>
				<mesh filename="package://robotiq_description/meshes/visual/2f_85/right_inner_knuckle.dae" />
			</geometry>
		</visual>
		<collision>
			<geometry>
				<mesh filename="package://robotiq_description/meshes/collision/2f_85/right_inner_knuckle.stl" />
			</geometry>
		</collision>
		<inertial>
			<origin xyz="-0.01926824 5.001e-05 0.02222178" rpy="0 0 0" />
			<mass value="2.969376448e-02" />
			<inertia ixx="9.42456e-06" iyy="8.69056e-06" izz="8.33824e-06" ixy="0.0" ixz="3.9636e-06" iyz="0.0" />
		</inertial>
	</link>
	<link name="gripper_robotiq_85_left_finger_tip_link">
		<visual>
			<geometry>
				<mesh filename="package://robotiq_description/meshes/visual/2f_85/left_finger_tip.dae" />
			</geometry>
		</visual>
		<collision>
			<geometry>
				<mesh filename="package://robotiq_description/meshes/collision/2f_85/left_finger_tip.stl" />
			</geometry>
			<surface>
				<friction>
					<ode>
						<mu1>
							100000.0
						</mu1>
						<mu2>
							100000.0
						</mu2>
					</ode>
				</friction>
				<contact>
					<ode>
						<kp>
							1e+5
						</kp>
						<kd>
							1
						</kd>
						<soft_cfm>
							0
						</soft_cfm>
						<soft_erp>
							0.2
						</soft_erp>
						<minDepth>
							0.002
						</minDepth>
						<maxVel>
							0
						</maxVel>
					</ode>
				</contact>
			</surface>
		</collision>
		<inertial>
			<origin xyz="-0.01456706 -0.0008 0.01649701" rpy="0 0 0" />
			<mass value="4.268588744e-02" />
			<inertia ixx="1.048152e-05" iyy="1.197888e-05" izz="4.22784e-06" ixy="0.0" ixz="3.5232e-6" iyz="0.0" />
		</inertial>
	</link>
	<link name="gripper_robotiq_85_right_finger_tip_link">
		<visual>
			<geometry>
				<mesh filename="package://robotiq_description/meshes/visual/2f_85/right_finger_tip.dae" />
			</geometry>
		</visual>
		<collision>
			<geometry>
				<mesh filename="package://robotiq_description/meshes/collision/2f_85/right_finger_tip.stl" />
			</geometry>
			<surface>
				<friction>
					<ode>
						<mu1>
							100000.0
						</mu1>
						<mu2>
							100000.0
						</mu2>
					</ode>
				</friction>
				<contact>
					<ode>
						<kp>
							1e+5
						</kp>
						<kd>
							1
						</kd>
						<soft_cfm>
							0
						</soft_cfm>
						<soft_erp>
							0.2
						</soft_erp>
						<minDepth>
							0.002
						</minDepth>
						<maxVel>
							0
						</maxVel>
					</ode>
				</contact>
			</surface>
		</collision>
		<inertial>
			<origin xyz="0.01456706 5e-05 0.01649701" rpy="0 0 0" />
			<mass value="4.268588744e-02" />
			<inertia ixx="1.048152e-05" iyy="1.197888e-05" izz="4.22784e-06" ixy="0.0" ixz="-3.5232e-06" iyz="0.0" />
		</inertial>
	</link>
	<joint name="gripper_robotiq_85_base_joint" type="fixed">
		<parent link="tool0" />
		<child link="gripper_robotiq_85_base_link" />
		<insert_block name="origin" />
	</joint>
	<joint name="gripper_robotiq_85_left_knuckle_joint" type="fixed">
		<parent link="gripper_robotiq_85_base_link" />
		<child link="gripper_robotiq_85_left_knuckle_link" />
		<axis xyz="0 -1 0" />
		<origin xyz="0.03060114 0.0 0.05490452" rpy="0 0 0" />
		<limit lower="0.0" upper="0.8" velocity="0.5" effort="50" />
	</joint>
	<joint name="gripper_robotiq_85_right_knuckle_joint" type="fixed">
		<parent link="gripper_robotiq_85_base_link" />
		<child link="gripper_robotiq_85_right_knuckle_link" />
		<axis xyz="0 -1 0" />
		<origin xyz="-0.03060114 0.0 0.05490452" rpy="0 0 0" />
		<limit lower="-0.8" upper="0.0" velocity="0.5" effort="50" />
		<mimic joint="gripper_robotiq_85_left_knuckle_joint" multiplier="-1" />
	</joint>
	<joint name="gripper_robotiq_85_left_finger_joint" type="fixed">
		<parent link="gripper_robotiq_85_left_knuckle_link" />
		<child link="gripper_robotiq_85_left_finger_link" />
		<origin xyz="0.03152616 0.0 -0.00376347" rpy="0 0 0" />
	</joint>
	<joint name="gripper_robotiq_85_right_finger_joint" type="fixed">
		<parent link="gripper_robotiq_85_right_knuckle_link" />
		<child link="gripper_robotiq_85_right_finger_link" />
		<origin xyz="-0.03152616 0.0 -0.00376347" rpy="0 0 0" />
	</joint>
	<joint name="gripper_robotiq_85_left_inner_knuckle_joint" type="fixed">
		<parent link="gripper_robotiq_85_base_link" />
		<child link="gripper_robotiq_85_left_inner_knuckle_link" />
		<axis xyz="0 -1 0" />
		<origin xyz="0.0127 0.0 0.06142" rpy="0 0 0" />
		<mimic joint="gripper_robotiq_85_left_knuckle_joint" />
	</joint>
	<joint name="gripper_robotiq_85_right_inner_knuckle_joint" type="fixed">
		<parent link="gripper_robotiq_85_base_link" />
		<child link="gripper_robotiq_85_right_inner_knuckle_link" />
		<axis xyz="0 -1 0" />
		<origin xyz="-0.0127 0.0 0.06142" rpy="0 0 0" />
		<mimic joint="gripper_robotiq_85_left_knuckle_joint" multiplier="-1" />
	</joint>
	<joint name="gripper_robotiq_85_left_finger_tip_joint" type="fixed">
		<parent link="gripper_robotiq_85_left_finger_link" />
		<child link="gripper_robotiq_85_left_finger_tip_link" />
		<axis xyz="0 -1 0" />
		<origin xyz="0.00563134 0.0 0.04718515" rpy="0 0 0" />
		<mimic joint="gripper_robotiq_85_left_knuckle_joint" multiplier="-1" />
	</joint>
	<joint name="gripper_robotiq_85_right_finger_tip_joint" type="fixed">
		<parent link="gripper_robotiq_85_right_finger_link" />
		<child link="gripper_robotiq_85_right_finger_tip_link" />
		<axis xyz="0 -1 0" />
		<origin xyz="-0.00563134 0.0 0.04718515" rpy="0 0 0" />
		<mimic joint="gripper_robotiq_85_left_knuckle_joint" />
	</joint>

	<link name="gripper_link" />
	<joint name="tool0-gripper" type="fixed">
		<parent link="tool0" />
		<child link="gripper_link" />
		<origin xyz="0 0 0.12" rpy="0 0 0" />
	</joint>
</robot>
